Workbook

Sheet README
A1: GoodBelly - Decision Sciences II - Excel Analysis Workbook
A3: Purpose | B3: Reproducible Excel analysis supporting GoodBelly_Final_Report. Every regression is run with LINEST on the Analysis Data sheet; p-values, CIs, diagnostics, VIFs and influence measures are Excel formulas.
A4: Source data | B4: "Real Data" sheet of Case_Study_Dataset.xlsx copied unchanged to Raw Data (1386 rows). The Explanation sheet (variable dictionary) is not used for numbers. No answer/solution sheets exist in the supplied workbook; none were used.
A5: Colour code | B5: Blue font = input/typed value; black = formula/calculation; yellow fill, bold = key output.
A6: Sheet order | B6: Raw Data -> Analysis Data (renamed variables, EndRep, model blocks) -> Data Audit -> Descriptive Stats -> Correlations -> Baseline Models -> Full MLR -> Variable Selection -> Interaction Analysis -> Final Model -> Demo Analysis -> Endcap Analysis -> Residual Diagnostics -> VIF -> Outliers -> Influence -> Model Comparison -> Excel vs JASP -> Final Results.
A7: Derived variables | B7: Variable -> Formula -> Reason: EndRep -> Endcap × Sales Rep (=Endcap*Rep, Analysis Data col L) -> tests whether the Endcap effect depends on regional-rep presence. All other variables are the original columns renamed (Units Sold=Sales, Average Retail Price=Price, Sales Rep=Rep, Demo1-3=D13, Demo4-5=D45, Natural Retailers=Natural, Fitness Centers=Fitness).
A8: Dummy coding | B8: Rep, Endcap, Demo, D13, D45 are 0/1 as supplied; reference category = 0 for each. Intercept = predicted sales with all dummies 0 and Price = 0.
A9: Items computed outside Excel | B9: Stepwise logs (Variable Selection), other interaction candidates, sensitivity re-fits (region/week/store dummies, outlier exclusion), cluster-robust SEs and the Python reference column are static values from analysis.py (statsmodels), labelled "static". Everything else is formula-driven.
A10: JASP | B10: NOT RUN. See Excel vs JASP sheet. A JASP-ready dataset and model specification are supplied separately.
A11: Data discrepancy | B11: Case text: 10 weeks. Dataset: 11 weekly dates (4 May-13 Jul 2010) x 126 stores = 1,386 rows. The dataset was used as supplied. Region "NA" is a real code, not missing.
A12: Recalculation | B12: Open in Excel; formulas recalculate automatically. LINEST/MMULT/MINVERSE cells are array formulas - do not edit partially.

Sheet Raw Data
A1: Date | B1: Region | C1: Store | D1: Units Sold | E1: Average Retail Price | F1: Sales Rep | G1: Endcap | H1: Demo | I1: Demo1-3 | J1: Demo4-5 | K1: Natural | L1: Fitness
A2: 40302 | B2: FL | C2: Biscayne (aka Aventura) | D2: 150.70209 | E2: 4.39 | F2: 0 | G2: 0 | H2: 0 | I2: 0 | J2: 0 | K2: 1 | L2: 0
A3: 40309 | B3: FL | C3: Biscayne (aka Aventura) | D3: 197.4038 | E3: 3.9976923 | F3: 0 | G3: 0 | H3: 0 | I3: 0 | J3: 0 | K3: 1 | L3: 0
A4: 40316 | B4: FL | C4: Biscayne (aka Aventura) | D4: 235.10617 | E4: 3.8092308 | F4: 0 | G4: 0 | H4: 0 | I4: 0 | J4: 0 | K4: 1 | L4: 0
A5: 40323 | B5: FL | C5: Biscayne (aka Aventura) | D5: 226.69243 | E5: 3.835 | F5: 0 | G5: 0 | H5: 0 | I5: 0 | J5: 0 | K5: 1 | L5: 0
A6: 40330 | B6: FL | C6: Biscayne (aka Aventura) | D6: 257.68815 | E6: 3.9025 | F6: 0 | G6: 0 | H6: 0 | I6: 0 | J6: 0 | K6: 1 | L6: 0
A7: 40337 | B7: FL | C7: Biscayne (aka Aventura) | D7: 132.95719 | E7: 4.4976923 | F7: 0 | G7: 0 | H7: 0 | I7: 0 | J7: 0 | K7: 1 | L7: 0
A8: 40344 | B8: FL | C8: Biscayne (aka Aventura) | D8: 221.88997 | E8: 4.1166667 | F8: 0 | G8: 0 | H8: 0 | I8: 0 | J8: 0 | K8: 1 | L8: 0
A9: 40351 | B9: FL | C9: Biscayne (aka Aventura) | D9: 245.88136 | E9: 4.1166667 | F9: 0 | G9: 0 | H9: 0 | I9: 0 | J9: 0 | K9: 1 | L9: 0
A10: 40358 | B10: FL | C10: Biscayne (aka Aventura) | D10: 156.10253 | E10: 4.1166667 | F10: 0 | G10: 0 | H10: 0 | I10: 0 | J10: 0 | K10: 4 | L10: 0
A11: 40365 | B11: FL | C11: Biscayne (aka Aventura) | D11: 200.10397 | E11: 3.7473333 | F11: 0 | G11: 0 | H11: 0 | I11: 0 | J11: 0 | K11: 1 | L11: 0
A12: 40372 | B12: FL | C12: Biscayne (aka Aventura) | D12: 128.396 | E12: 4.0125 | F12: 0 | G12: 0 | H12: 0 | I12: 0 | J12: 0 | K12: 1 | L12: 0
A13: 40302 | B13: FL | C13: Boca Raton | D13: 142.77821 | E13: 4.39 | F13: 0 | G13: 0 | H13: 0 | I13: 0 | J13: 0 | K13: 0 | L13: 4
... A1387: 40372 | B1387: SW | C1387: Veterans | D1387: 166.89303 | E1387: 4.19 | F1387: 0 | G1387: 0 | H1387: 0 | I1387: 0 | J1387: 0 | K1387: 0 | L1387: 1

Sheet Analysis Data
A1: Store | B1: Date | C1: Sales | D1: Price | E1: Rep | F1: Endcap | G1: Demo | H1: D13 | I1: D45 | J1: Natural | K1: Fitness | L1: EndRep | N1: const | O1: Price | P1: Rep | Q1: Endcap | R1: Demo | S1: D13 | T1: D45 | U1: EndRep | W1: Price | X1: Rep | Y1: Endcap | Z1: EndRep | AA1: Demo | AC1: Price | AD1: Rep | AE1: Demo | AF1: D13 | AG1: D45 | AH1: EndRep | AJ1: Block guide (all columns are formulas linked to Raw Data):
A2: ='Raw Data'!C2 -> Biscayne (aka Aventura) | B2: ='Raw Data'!A2 -> 40302 | C2: ='Raw Data'!D2 -> 150.70209 | D2: ='Raw Data'!E2 -> 4.39 | E2: ='Raw Data'!F2 -> 0 | F2: ='Raw Data'!G2 -> 0 | G2: ='Raw Data'!H2 -> 0 | H2: ='Raw Data'!I2 -> 0 | I2: ='Raw Data'!J2 -> 0 | J2: ='Raw Data'!K2 -> 1 | K2: ='Raw Data'!L2 -> 0 | L2: =F2*E2 -> 0 | N2: 1 | O2: =D2 -> 4.39 | P2: =E2 -> 0 | Q2: =F2 -> 0 | R2: =G2 -> 0 | S2: =H2 -> 0 | T2: =I2 -> 0 | U2: =L2 -> 0 | W2: =D2 -> 4.39 | X2: =E2 -> 0 | Y2: =F2 -> 0 | Z2: =L2 -> 0 | AA2: =G2 -> 0 | AC2: =D2 -> 4.39 | AD2: =E2 -> 0 | AE2: =G2 -> 0 | AF2: =H2 -> 0 | AG2: =I2 -> 0 | AH2: =L2 -> 0 | AJ2: A:K = analysis variables (renamed). L = Endcap x Sales Rep (=Endcap*Sales Rep).
A3: ='Raw Data'!C3 -> Biscayne (aka Aventura) | B3: ='Raw Data'!A3 -> 40309 | C3: ='Raw Data'!D3 -> 197.4038 | D3: ='Raw Data'!E3 -> 3.9976923 | E3: ='Raw Data'!F3 -> 0 | F3: ='Raw Data'!G3 -> 0 | G3: ='Raw Data'!H3 -> 0 | H3: ='Raw Data'!I3 -> 0 | I3: ='Raw Data'!J3 -> 0 | J3: ='Raw Data'!K3 -> 1 | K3: ='Raw Data'!L3 -> 0 | L3: =F3*E3 -> 0 | N3: 1 | O3: =D3 -> 3.9976923 | P3: =E3 -> 0 | Q3: =F3 -> 0 | R3: =G3 -> 0 | S3: =H3 -> 0 | T3: =I3 -> 0 | U3: =L3 -> 0 | W3: =D3 -> 3.9976923 | X3: =E3 -> 0 | Y3: =F3 -> 0 | Z3: =L3 -> 0 | AA3: =G3 -> 0 | AC3: =D3 -> 3.9976923 | AD3: =E3 -> 0 | AE3: =G3 -> 0 | AF3: =H3 -> 0 | AG3: =I3 -> 0 | AH3: =L3 -> 0 | AJ3: D:K = predictors of Model 1 (Full MLR); D:L adds the interaction (Model 3).
A4: ='Raw Data'!C4 -> Biscayne (aka Aventura) | B4: ='Raw Data'!A4 -> 40316 | C4: ='Raw Data'!D4 -> 235.10617 | D4: ='Raw Data'!E4 -> 3.8092308 | E4: ='Raw Data'!F4 -> 0 | F4: ='Raw Data'!G4 -> 0 | G4: ='Raw Data'!H4 -> 0 | H4: ='Raw Data'!I4 -> 0 | I4: ='Raw Data'!J4 -> 0 | J4: ='Raw Data'!K4 -> 1 | K4: ='Raw Data'!L4 -> 0 | L4: =F4*E4 -> 0 | N4: 1 | O4: =D4 -> 3.8092308 | P4: =E4 -> 0 | Q4: =F4 -> 0 | R4: =G4 -> 0 | S4: =H4 -> 0 | T4: =I4 -> 0 | U4: =L4 -> 0 | W4: =D4 -> 3.8092308 | X4: =E4 -> 0 | Y4: =F4 -> 0 | Z4: =L4 -> 0 | AA4: =G4 -> 0 | AC4: =D4 -> 3.8092308 | AD4: =E4 -> 0 | AE4: =G4 -> 0 | AF4: =H4 -> 0 | AG4: =I4 -> 0 | AH4: =L4 -> 0 | AJ4: N:U = [constant + final-model predictors] used by Final Model, diagnostics, leverage.
A5: ='Raw Data'!C5 -> Biscayne (aka Aventura) | B5: ='Raw Data'!A5 -> 40323 | C5: ='Raw Data'!D5 -> 226.69243 | D5: ='Raw Data'!E5 -> 3.835 | E5: ='Raw Data'!F5 -> 0 | F5: ='Raw Data'!G5 -> 0 | G5: ='Raw Data'!H5 -> 0 | H5: ='Raw Data'!I5 -> 0 | I5: ='Raw Data'!J5 -> 0 | J5: ='Raw Data'!K5 -> 1 | K5: ='Raw Data'!L5 -> 0 | L5: =F5*E5 -> 0 | N5: 1 | O5: =D5 -> 3.835 | P5: =E5 -> 0 | Q5: =F5 -> 0 | R5: =G5 -> 0 | S5: =H5 -> 0 | T5: =I5 -> 0 | U5: =L5 -> 0 | W5: =D5 -> 3.835 | X5: =E5 -> 0 | Y5: =F5 -> 0 | Z5: =L5 -> 0 | AA5: =G5 -> 0 | AC5: =D5 -> 3.835 | AD5: =E5 -> 0 | AE5: =G5 -> 0 | AF5: =H5 -> 0 | AG5: =I5 -> 0 | AH5: =L5 -> 0 | AJ5: W:AA = Price, Rep, Endcap, Endcap x Rep, Demo (restricted model for partial-F tests).
A6: ='Raw Data'!C6 -> Biscayne (aka Aventura) | B6: ='Raw Data'!A6 -> 40330 | C6: ='Raw Data'!D6 -> 257.68815 | D6: ='Raw Data'!E6 -> 3.9025 | E6: ='Raw Data'!F6 -> 0 | F6: ='Raw Data'!G6 -> 0 | G6: ='Raw Data'!H6 -> 0 | H6: ='Raw Data'!I6 -> 0 | I6: ='Raw Data'!J6 -> 0 | J6: ='Raw Data'!K6 -> 1 | K6: ='Raw Data'!L6 -> 0 | L6: =F6*E6 -> 0 | N6: 1 | O6: =D6 -> 3.9025 | P6: =E6 -> 0 | Q6: =F6 -> 0 | R6: =G6 -> 0 | S6: =H6 -> 0 | T6: =I6 -> 0 | U6: =L6 -> 0 | W6: =D6 -> 3.9025 | X6: =E6 -> 0 | Y6: =F6 -> 0 | Z6: =L6 -> 0 | AA6: =G6 -> 0 | AC6: =D6 -> 3.9025 | AD6: =E6 -> 0 | AE6: =G6 -> 0 | AF6: =H6 -> 0 | AG6: =I6 -> 0 | AH6: =L6 -> 0 | AJ6: AC:AH = final model WITHOUT the Endcap main effect (restricted model).
A7: ='Raw Data'!C7 -> Biscayne (aka Aventura) | B7: ='Raw Data'!A7 -> 40337 | C7: ='Raw Data'!D7 -> 132.95719 | D7: ='Raw Data'!E7 -> 4.4976923 | E7: ='Raw Data'!F7 -> 0 | F7: ='Raw Data'!G7 -> 0 | G7: ='Raw Data'!H7 -> 0 | H7: ='Raw Data'!I7 -> 0 | I7: ='Raw Data'!J7 -> 0 | J7: ='Raw Data'!K7 -> 1 | K7: ='Raw Data'!L7 -> 0 | L7: =F7*E7 -> 0 | N7: 1 | O7: =D7 -> 4.4976923 | P7: =E7 -> 0 | Q7: =F7 -> 0 | R7: =G7 -> 0 | S7: =H7 -> 0 | T7: =I7 -> 0 | U7: =L7 -> 0 | W7: =D7 -> 4.4976923 | X7: =E7 -> 0 | Y7: =F7 -> 0 | Z7: =L7 -> 0 | AA7: =G7 -> 0 | AC7: =D7 -> 4.4976923 | AD7: =E7 -> 0 | AE7: =G7 -> 0 | AF7: =H7 -> 0 | AG7: =I7 -> 0 | AH7: =L7 -> 0
A8: ='Raw Data'!C8 -> Biscayne (aka Aventura) | B8: ='Raw Data'!A8 -> 40344 | C8: ='Raw Data'!D8 -> 221.88997 | D8: ='Raw Data'!E8 -> 4.1166667 | E8: ='Raw Data'!F8 -> 0 | F8: ='Raw Data'!G8 -> 0 | G8: ='Raw Data'!H8 -> 0 | H8: ='Raw Data'!I8 -> 0 | I8: ='Raw Data'!J8 -> 0 | J8: ='Raw Data'!K8 -> 1 | K8: ='Raw Data'!L8 -> 0 | L8: =F8*E8 -> 0 | N8: 1 | O8: =D8 -> 4.1166667 | P8: =E8 -> 0 | Q8: =F8 -> 0 | R8: =G8 -> 0 | S8: =H8 -> 0 | T8: =I8 -> 0 | U8: =L8 -> 0 | W8: =D8 -> 4.1166667 | X8: =E8 -> 0 | Y8: =F8 -> 0 | Z8: =L8 -> 0 | AA8: =G8 -> 0 | AC8: =D8 -> 4.1166667 | AD8: =E8 -> 0 | AE8: =G8 -> 0 | AF8: =H8 -> 0 | AG8: =I8 -> 0 | AH8: =L8 -> 0
A9: ='Raw Data'!C9 -> Biscayne (aka Aventura) | B9: ='Raw Data'!A9 -> 40351 | C9: ='Raw Data'!D9 -> 245.88136 | D9: ='Raw Data'!E9 -> 4.1166667 | E9: ='Raw Data'!F9 -> 0 | F9: ='Raw Data'!G9 -> 0 | G9: ='Raw Data'!H9 -> 0 | H9: ='Raw Data'!I9 -> 0 | I9: ='Raw Data'!J9 -> 0 | J9: ='Raw Data'!K9 -> 1 | K9: ='Raw Data'!L9 -> 0 | L9: =F9*E9 -> 0 | N9: 1 | O9: =D9 -> 4.1166667 | P9: =E9 -> 0 | Q9: =F9 -> 0 | R9: =G9 -> 0 | S9: =H9 -> 0 | T9: =I9 -> 0 | U9: =L9 -> 0 | W9: =D9 -> 4.1166667 | X9: =E9 -> 0 | Y9: =F9 -> 0 | Z9: =L9 -> 0 | AA9: =G9 -> 0 | AC9: =D9 -> 4.1166667 | AD9: =E9 -> 0 | AE9: =G9 -> 0 | AF9: =H9 -> 0 | AG9: =I9 -> 0 | AH9: =L9 -> 0
A10: ='Raw Data'!C10 -> Biscayne (aka Aventura) | B10: ='Raw Data'!A10 -> 40358 | C10: ='Raw Data'!D10 -> 156.10253 | D10: ='Raw Data'!E10 -> 4.1166667 | E10: ='Raw Data'!F10 -> 0 | F10: ='Raw Data'!G10 -> 0 | G10: ='Raw Data'!H10 -> 0 | H10: ='Raw Data'!I10 -> 0 | I10: ='Raw Data'!J10 -> 0 | J10: ='Raw Data'!K10 -> 4 | K10: ='Raw Data'!L10 -> 0 | L10: =F10*E10 -> 0 | N10: 1 | O10: =D10 -> 4.1166667 | P10: =E10 -> 0 | Q10: =F10 -> 0 | R10: =G10 -> 0 | S10: =H10 -> 0 | T10: =I10 -> 0 | U10: =L10 -> 0 | W10: =D10 -> 4.1166667 | X10: =E10 -> 0 | Y10: =F10 -> 0 | Z10: =L10 -> 0 | AA10: =G10 -> 0 | AC10: =D10 -> 4.1166667 | AD10: =E10 -> 0 | AE10: =G10 -> 0 | AF10: =H10 -> 0 | AG10: =I10 -> 0 | AH10: =L10 -> 0
A11: ='Raw Data'!C11 -> Biscayne (aka Aventura) | B11: ='Raw Data'!A11 -> 40365 | C11: ='Raw Data'!D11 -> 200.10397 | D11: ='Raw Data'!E11 -> 3.7473333 | E11: ='Raw Data'!F11 -> 0 | F11: ='Raw Data'!G11 -> 0 | G11: ='Raw Data'!H11 -> 0 | H11: ='Raw Data'!I11 -> 0 | I11: ='Raw Data'!J11 -> 0 | J11: ='Raw Data'!K11 -> 1 | K11: ='Raw Data'!L11 -> 0 | L11: =F11*E11 -> 0 | N11: 1 | O11: =D11 -> 3.7473333 | P11: =E11 -> 0 | Q11: =F11 -> 0 | R11: =G11 -> 0 | S11: =H11 -> 0 | T11: =I11 -> 0 | U11: =L11 -> 0 | W11: =D11 -> 3.7473333 | X11: =E11 -> 0 | Y11: =F11 -> 0 | Z11: =L11 -> 0 | AA11: =G11 -> 0 | AC11: =D11 -> 3.7473333 | AD11: =E11 -> 0 | AE11: =G11 -> 0 | AF11: =H11 -> 0 | AG11: =I11 -> 0 | AH11: =L11 -> 0
A12: ='Raw Data'!C12 -> Biscayne (aka Aventura) | B12: ='Raw Data'!A12 -> 40372 | C12: ='Raw Data'!D12 -> 128.396 | D12: ='Raw Data'!E12 -> 4.0125 | E12: ='Raw Data'!F12 -> 0 | F12: ='Raw Data'!G12 -> 0 | G12: ='Raw Data'!H12 -> 0 | H12: ='Raw Data'!I12 -> 0 | I12: ='Raw Data'!J12 -> 0 | J12: ='Raw Data'!K12 -> 1 | K12: ='Raw Data'!L12 -> 0 | L12: =F12*E12 -> 0 | N12: 1 | O12: =D12 -> 4.0125 | P12: =E12 -> 0 | Q12: =F12 -> 0 | R12: =G12 -> 0 | S12: =H12 -> 0 | T12: =I12 -> 0 | U12: =L12 -> 0 | W12: =D12 -> 4.0125 | X12: =E12 -> 0 | Y12: =F12 -> 0 | Z12: =L12 -> 0 | AA12: =G12 -> 0 | AC12: =D12 -> 4.0125 | AD12: =E12 -> 0 | AE12: =G12 -> 0 | AF12: =H12 -> 0 | AG12: =I12 -> 0 | AH12: =L12 -> 0
A13: ='Raw Data'!C13 -> Boca Raton | B13: ='Raw Data'!A13 -> 40302 | C13: ='Raw Data'!D13 -> 142.77821 | D13: ='Raw Data'!E13 -> 4.39 | E13: ='Raw Data'!F13 -> 0 | F13: ='Raw Data'!G13 -> 0 | G13: ='Raw Data'!H13 -> 0 | H13: ='Raw Data'!I13 -> 0 | I13: ='Raw Data'!J13 -> 0 | J13: ='Raw Data'!K13 -> 0 | K13: ='Raw Data'!L13 -> 4 | L13: =F13*E13 -> 0 | N13: 1 | O13: =D13 -> 4.39 | P13: =E13 -> 0 | Q13: =F13 -> 0 | R13: =G13 -> 0 | S13: =H13 -> 0 | T13: =I13 -> 0 | U13: =L13 -> 0 | W13: =D13 -> 4.39 | X13: =E13 -> 0 | Y13: =F13 -> 0 | Z13: =L13 -> 0 | AA13: =G13 -> 0 | AC13: =D13 -> 4.39 | AD13: =E13 -> 0 | AE13: =G13 -> 0 | AF13: =H13 -> 0 | AG13: =I13 -> 0 | AH13: =L13 -> 0
A14: ='Raw Data'!C14 -> Boca Raton | B14: ='Raw Data'!A14 -> 40309 | C14: ='Raw Data'!D14 -> 237.54455 | D14: ='Raw Data'!E14 -> 4.2354545 | E14: ='Raw Data'!F14 -> 0 | F14: ='Raw Data'!G14 -> 0 | G14: ='Raw Data'!H14 -> 0 | H14: ='Raw Data'!I14 -> 0 | I14: ='Raw Data'!J14 -> 0 | J14: ='Raw Data'!K14 -> 0 | K14: ='Raw Data'!L14 -> 4 | L14: =F14*E14 -> 0 | N14: 1 | O14: =D14 -> 4.2354545 | P14: =E14 -> 0 | Q14: =F14 -> 0 | R14: =G14 -> 0 | S14: =H14 -> 0 | T14: =I14 -> 0 | U14: =L14 -> 0 | W14: =D14 -> 4.2354545 | X14: =E14 -> 0 | Y14: =F14 -> 0 | Z14: =L14 -> 0 | AA14: =G14 -> 0 | AC14: =D14 -> 4.2354545 | AD14: =E14 -> 0 | AE14: =G14 -> 0 | AF14: =H14 -> 0 | AG14: =I14 -> 0 | AH14: =L14 -> 0
A15: ='Raw Data'!C15 -> Boca Raton | B15: ='Raw Data'!A15 -> 40316 | C15: ='Raw Data'!D15 -> 141.5333 | D15: ='Raw Data'!E15 -> 3.8092308 | E15: ='Raw Data'!F15 -> 0 | F15: ='Raw Data'!G15 -> 0 | G15: ='Raw Data'!H15 -> 0 | H15: ='Raw Data'!I15 -> 0 | I15: ='Raw Data'!J15 -> 0 | J15: ='Raw Data'!K15 -> 0 | K15: ='Raw Data'!L15 -> 4 | L15: =F15*E15 -> 0 | N15: 1 | O15: =D15 -> 3.8092308 | P15: =E15 -> 0 | Q15: =F15 -> 0 | R15: =G15 -> 0 | S15: =H15 -> 0 | T15: =I15 -> 0 | U15: =L15 -> 0 | W15: =D15 -> 3.8092308 | X15: =E15 -> 0 | Y15: =F15 -> 0 | Z15: =L15 -> 0 | AA15: =G15 -> 0 | AC15: =D15 -> 3.8092308 | AD15: =E15 -> 0 | AE15: =G15 -> 0 | AF15: =H15 -> 0 | AG15: =I15 -> 0 | AH15: =L15 -> 0
A16: ='Raw Data'!C16 -> Boca Raton | B16: ='Raw Data'!A16 -> 40323 | C16: ='Raw Data'!D16 -> 158.07395 | D16: ='Raw Data'!E16 -> 3.8092308 | E16: ='Raw Data'!F16 -> 0 | F16: ='Raw Data'!G16 -> 0 | G16: ='Raw Data'!H16 -> 0 | H16: ='Raw Data'!I16 -> 0 | I16: ='Raw Data'!J16 -> 0 | J16: ='Raw Data'!K16 -> 0 | K16: ='Raw Data'!L16 -> 4 | L16: =F16*E16 -> 0 | N16: 1 | O16: =D16 -> 3.8092308 | P16: =E16 -> 0 | Q16: =F16 -> 0 | R16: =G16 -> 0 | S16: =H16 -> 0 | T16: =I16 -> 0 | U16: =L16 -> 0 | W16: =D16 -> 3.8092308 | X16: =E16 -> 0 | Y16: =F16 -> 0 | Z16: =L16 -> 0 | AA16: =G16 -> 0 | AC16: =D16 -> 3.8092308 | AD16: =E16 -> 0 | AE16: =G16 -> 0 | AF16: =H16 -> 0 | AG16: =I16 -> 0 | AH16: =L16 -> 0
A17: ='Raw Data'!C17 -> Boca Raton | B17: ='Raw Data'!A17 -> 40330 | C17: ='Raw Data'!D17 -> 255.11774 | D17: ='Raw Data'!E17 -> 4.055625 | E17: ='Raw Data'!F17 -> 0 | F17: ='Raw Data'!G17 -> 0 | G17: ='Raw Data'!H17 -> 0 | H17: ='Raw Data'!I17 -> 0 | I17: ='Raw Data'!J17 -> 0 | J17: ='Raw Data'!K17 -> 0 | K17: ='Raw Data'!L17 -> 4 | L17: =F17*E17 -> 0 | N17: 1 | O17: =D17 -> 4.055625 | P17: =E17 -> 0 | Q17: =F17 -> 0 | R17: =G17 -> 0 | S17: =H17 -> 0 | T17: =I17 -> 0 | U17: =L17 -> 0 | W17: =D17 -> 4.055625 | X17: =E17 -> 0 | Y17: =F17 -> 0 | Z17: =L17 -> 0 | AA17: =G17 -> 0 | AC17: =D17 -> 4.055625 | AD17: =E17 -> 0 | AE17: =G17 -> 0 | AF17: =H17 -> 0 | AG17: =I17 -> 0 | AH17: =L17 -> 0
A18: ='Raw Data'!C18 -> Boca Raton | B18: ='Raw Data'!A18 -> 40337 | C18: ='Raw Data'!D18 -> 129.79363 | D18: ='Raw Data'!E18 -> 4.3833333 | E18: ='Raw Data'!F18 -> 0 | F18: ='Raw Data'!G18 -> 0 | G18: ='Raw Data'!H18 -> 0 | H18: ='Raw Data'!I18 -> 0 | I18: ='Raw Data'!J18 -> 0 | J18: ='Raw Data'!K18 -> 0 | K18: ='Raw Data'!L18 -> 4 | L18: =F18*E18 -> 0 | N18: 1 | O18: =D18 -> 4.3833333 | P18: =E18 -> 0 | Q18: =F18 -> 0 | R18: =G18 -> 0 | S18: =H18 -> 0 | T18: =I18 -> 0 | U18: =L18 -> 0 | W18: =D18 -> 4.3833333 | X18: =E18 -> 0 | Y18: =F18 -> 0 | Z18: =L18 -> 0 | AA18: =G18 -> 0 | AC18: =D18 -> 4.3833333 | AD18: =E18 -> 0 | AE18: =G18 -> 0 | AF18: =H18 -> 0 | AG18: =I18 -> 0 | AH18: =L18 -> 0
... A1387: ='Raw Data'!C1387 -> Veterans | B1387: ='Raw Data'!A1387 -> 40372 | C1387: ='Raw Data'!D1387 -> 166.89303 | D1387: ='Raw Data'!E1387 -> 4.19 | E1387: ='Raw Data'!F1387 -> 0 | F1387: ='Raw Data'!G1387 -> 0 | G1387: ='Raw Data'!H1387 -> 0 | H1387: ='Raw Data'!I1387 -> 0 | I1387: ='Raw Data'!J1387 -> 0 | J1387: ='Raw Data'!K1387 -> 0 | K1387: ='Raw Data'!L1387 -> 1 | L1387: =F1387*E1387 -> 0 | N1387: 1 | O1387: =D1387 -> 4.19 | P1387: =E1387 -> 0 | Q1387: =F1387 -> 0 | R1387: =G1387 -> 0 | S1387: =H1387 -> 0 | T1387: =I1387 -> 0 | U1387: =L1387 -> 0 | W1387: =D1387 -> 4.19 | X1387: =E1387 -> 0 | Y1387: =F1387 -> 0 | Z1387: =L1387 -> 0 | AA1387: =G1387 -> 0 | AC1387: =D1387 -> 4.19 | AD1387: =E1387 -> 0 | AE1387: =G1387 -> 0 | AF1387: =H1387 -> 0 | AG1387: =I1387 -> 0 | AH1387: =L1387 -> 0

Sheet Data Audit
A1: DATA AUDIT
A3: Structure checks | B3: Value | C3: Comment
A4: Rows (observations) | B4: =COUNTA('Raw Data'!$C$2:$C$1387) -> 1386 | C4: Matches case: 1,386 store-week observations
A5: Columns | B5: =COUNTA('Raw Data'!$A$1:$L$1) -> 12 | C5: 12 columns in Real Data sheet
A6: Distinct stores | B6: =SUMPRODUCT(1/COUNTIF('Raw Data'!$C$2:$C$1387,'Raw Data'!$C$2:$C$1387)) -> 126 | C6: Matches case: 126 stores
A7: Distinct dates (weeks) | B7: =SUMPRODUCT(1/COUNTIF('Raw Data'!$A$2:$A$1387,'Raw Data'!$A$2:$A$1387)) -> 11 | C7: DISCREPANCY: dataset has 11 weekly dates (4 May - 13 Jul 2010); case Exhibit 1 says 10 weeks. 126 x 11 = 1,386 confirms 11 weeks. Dataset used as supplied.
A8: Observations per store (min) | B8: {=MIN(COUNTIF('Raw Data'!$C$2:$C$1387,'Raw Data'!$C$2:$C$1387))} -> 11 | C8: Balanced panel: every store has 11 weekly records (array calc)
A9: First date | B9: =MIN('Raw Data'!$A$2:$A$1387) -> 40302
A10: Last date | B10: =MAX('Raw Data'!$A$2:$A$1387) -> 40372
A11: Blank cells in numeric/dummy columns D:L | B11: =COUNTBLANK('Raw Data'!$D$2:$L$1387) -> 0 | C11: None
A12: Blank cells in Region | B12: =COUNTBLANK('Raw Data'!$B$2:$B$1387) -> 0 | C12: None. Region code "NA" (143 rows, 13 stores) is a genuine region code, not a missing value; software that reads "NA" as missing would silently drop these rows
A13: Rows with Region = "NA" | B13: =COUNTIF('Raw Data'!$B$2:$B$1387,"NA") -> 143 | C13: Kept in analysis (Region is not a model predictor)
A14: Exact duplicate rows | B14: 0 | C14: Checked in Python (all 12 fields identical): none
A15: Sales <= 0 | B15: =COUNTIF('Raw Data'!$D$2:$D$1387,"<=0") -> 0 | C15: None; minimum 47.6 units
A16: Stores whose Sales Rep flag changes during the window | B16: 10 | C16: Sales Rep is not constant within 10 stores (Python check). Treated as an observation-level indicator, as defined in the case.
A17: Stores whose Natural Retailers count changes | B17: 3 | C17: 3 stores (Python check)
A19: Variable summary
A20: Variable | B20: Count | C20: Distinct values | D20: Mean | E20: Median | F20: Std dev | G20: Min | H20: Max | I20: Type / coding
A21: Sales (Units Sold) | B21: =COUNT('Analysis Data'!$C$2:$C$1387) -> 1386 | C21: ="continuous" -> continuous | D21: =AVERAGE('Analysis Data'!$C$2:$C$1387) -> 253.82072 | E21: =MEDIAN('Analysis Data'!$C$2:$C$1387) -> 236.73527 | F21: =_xlfn.STDEV.S('Analysis Data'!$C$2:$C$1387) -> 110.99873 | G21: =MIN('Analysis Data'!$C$2:$C$1387) -> 47.559852 | H21: =MAX('Analysis Data'!$C$2:$C$1387) -> 1041.2003 | I21: Continuous - dependent variable
A22: Price (Avg Retail Price) | B22: =COUNT('Analysis Data'!$D$2:$D$1387) -> 1386 | C22: ="continuous" -> continuous | D22: =AVERAGE('Analysis Data'!$D$2:$D$1387) -> 4.1070929 | E22: =MEDIAN('Analysis Data'!$D$2:$D$1387) -> 4.0966667 | F22: =_xlfn.STDEV.S('Analysis Data'!$D$2:$D$1387) -> 0.46382837 | G22: =MIN('Analysis Data'!$D$2:$D$1387) -> 2.8892857 | H22: =MAX('Analysis Data'!$D$2:$D$1387) -> 6.2515385 | I22: Continuous, $
A23: Rep (Sales Rep) | B23: =COUNT('Analysis Data'!$E$2:$E$1387) -> 1386 | C23: =SUMPRODUCT(1/COUNTIF('Analysis Data'!$E$2:$E$1387,'Analysis Data'!$E$2:$E$1387)) -> 2 | D23: =AVERAGE('Analysis Data'!$E$2:$E$1387) -> 0.54978355 | E23: =MEDIAN('Analysis Data'!$E$2:$E$1387) -> 1 | F23: =_xlfn.STDEV.S('Analysis Data'!$E$2:$E$1387) -> 0.497695 | G23: =MIN('Analysis Data'!$E$2:$E$1387) -> 0 | H23: =MAX('Analysis Data'!$E$2:$E$1387) -> 1 | I23: Dummy 1 = regional rep, 0 = national only
A24: Endcap | B24: =COUNT('Analysis Data'!$F$2:$F$1387) -> 1386 | C24: =SUMPRODUCT(1/COUNTIF('Analysis Data'!$F$2:$F$1387,'Analysis Data'!$F$2:$F$1387)) -> 2 | D24: =AVERAGE('Analysis Data'!$F$2:$F$1387) -> 0.038239538 | E24: =MEDIAN('Analysis Data'!$F$2:$F$1387) -> 0 | F24: =_xlfn.STDEV.S('Analysis Data'!$F$2:$F$1387) -> 0.19184324 | G24: =MIN('Analysis Data'!$F$2:$F$1387) -> 0 | H24: =MAX('Analysis Data'!$F$2:$F$1387) -> 1 | I24: Dummy 1 = endcap promotion
A25: Demo | B25: =COUNT('Analysis Data'!$G$2:$G$1387) -> 1386 | C25: =SUMPRODUCT(1/COUNTIF('Analysis Data'!$G$2:$G$1387,'Analysis Data'!$G$2:$G$1387)) -> 2 | D25: =AVERAGE('Analysis Data'!$G$2:$G$1387) -> 0.058441558 | E25: =MEDIAN('Analysis Data'!$G$2:$G$1387) -> 0 | F25: =_xlfn.STDEV.S('Analysis Data'!$G$2:$G$1387) -> 0.23466119 | G25: =MIN('Analysis Data'!$G$2:$G$1387) -> 0 | H25: =MAX('Analysis Data'!$G$2:$G$1387) -> 1 | I25: Dummy: demo this week
A26: D13 (Demo1-3) | B26: =COUNT('Analysis Data'!$H$2:$H$1387) -> 1386 | C26: =SUMPRODUCT(1/COUNTIF('Analysis Data'!$H$2:$H$1387,'Analysis Data'!$H$2:$H$1387)) -> 2 | D26: =AVERAGE('Analysis Data'!$H$2:$H$1387) -> 0.15656566 | E26: =MEDIAN('Analysis Data'!$H$2:$H$1387) -> 0 | F26: =_xlfn.STDEV.S('Analysis Data'!$H$2:$H$1387) -> 0.36352193 | G26: =MIN('Analysis Data'!$H$2:$H$1387) -> 0 | H26: =MAX('Analysis Data'!$H$2:$H$1387) -> 1 | I26: Dummy: demo 1-3 weeks ago
A27: D45 (Demo4-5) | B27: =COUNT('Analysis Data'!$I$2:$I$1387) -> 1386 | C27: =SUMPRODUCT(1/COUNTIF('Analysis Data'!$I$2:$I$1387,'Analysis Data'!$I$2:$I$1387)) -> 2 | D27: =AVERAGE('Analysis Data'!$I$2:$I$1387) -> 0.075757576 | E27: =MEDIAN('Analysis Data'!$I$2:$I$1387) -> 0 | F27: =_xlfn.STDEV.S('Analysis Data'!$I$2:$I$1387) -> 0.26470535 | G27: =MIN('Analysis Data'!$I$2:$I$1387) -> 0 | H27: =MAX('Analysis Data'!$I$2:$I$1387) -> 1 | I27: Dummy: demo 4-5+ weeks ago
A28: Natural | B28: =COUNT('Analysis Data'!$J$2:$J$1387) -> 1386 | C28: =SUMPRODUCT(1/COUNTIF('Analysis Data'!$J$2:$J$1387,'Analysis Data'!$J$2:$J$1387)) -> 5 | D28: =AVERAGE('Analysis Data'!$J$2:$J$1387) -> 1.4487734 | E28: =MEDIAN('Analysis Data'!$J$2:$J$1387) -> 1 | F28: =_xlfn.STDEV.S('Analysis Data'!$J$2:$J$1387) -> 0.97509156 | G28: =MIN('Analysis Data'!$J$2:$J$1387) -> 0 | H28: =MAX('Analysis Data'!$J$2:$J$1387) -> 4 | I28: Count within 5 miles
A29: Fitness | B29: =COUNT('Analysis Data'!$K$2:$K$1387) -> 1386 | C29: =SUMPRODUCT(1/COUNTIF('Analysis Data'!$K$2:$K$1387,'Analysis Data'!$K$2:$K$1387)) -> 6 | D29: =AVERAGE('Analysis Data'!$K$2:$K$1387) -> 2.4761905 | E29: =MEDIAN('Analysis Data'!$K$2:$K$1387) -> 2 | F29: =_xlfn.STDEV.S('Analysis Data'!$K$2:$K$1387) -> 1.5927893 | G29: =MIN('Analysis Data'!$K$2:$K$1387) -> 0 | H29: =MAX('Analysis Data'!$K$2:$K$1387) -> 5 | I29: Count within 5 miles
A31: Dummy-variable counts (rows equal to 1)
A32: Rep | B32: =SUM('Analysis Data'!$E$2:$E$1387) -> 762
A33: Endcap | B33: =SUM('Analysis Data'!$F$2:$F$1387) -> 53
A34: Demo | B34: =SUM('Analysis Data'!$G$2:$G$1387) -> 81
A35: Demo1-3 | B35: =SUM('Analysis Data'!$H$2:$H$1387) -> 217
A36: Demo4-5 | B36: =SUM('Analysis Data'!$I$2:$I$1387) -> 105
A37: Endcap x Rep | B37: =SUM('Analysis Data'!$L$2:$L$1387) -> 36
A39: Outlier note: no data-entry errors found; max Sales 1,041 units (store with endcap + rep) is plausible given the Endcap x Rep effect; see Outliers sheet.

Sheet Descriptive Stats
A1: DESCRIPTIVE STATISTICS & UNADJUSTED PROMOTION COMPARISONS
A2: Unadjusted comparisons are descriptive; they do not control for other variables and are not causal estimates.
A4: Variable | B4: Mean | C4: Median | D4: Std dev | E4: Min | F4: Max | G4: N
A5: Sales (Units Sold) | B5: =AVERAGE('Analysis Data'!$C$2:$C$1387) -> 253.82072 | C5: =MEDIAN('Analysis Data'!$C$2:$C$1387) -> 236.73527 | D5: =_xlfn.STDEV.S('Analysis Data'!$C$2:$C$1387) -> 110.99873 | E5: =MIN('Analysis Data'!$C$2:$C$1387) -> 47.559852 | F5: =MAX('Analysis Data'!$C$2:$C$1387) -> 1041.2003 | G5: =COUNT('Analysis Data'!$C$2:$C$1387) -> 1386
A6: Price (Avg Retail Price) | B6: =AVERAGE('Analysis Data'!$D$2:$D$1387) -> 4.1070929 | C6: =MEDIAN('Analysis Data'!$D$2:$D$1387) -> 4.0966667 | D6: =_xlfn.STDEV.S('Analysis Data'!$D$2:$D$1387) -> 0.46382837 | E6: =MIN('Analysis Data'!$D$2:$D$1387) -> 2.8892857 | F6: =MAX('Analysis Data'!$D$2:$D$1387) -> 6.2515385 | G6: =COUNT('Analysis Data'!$D$2:$D$1387) -> 1386
A7: Rep (Sales Rep) | B7: =AVERAGE('Analysis Data'!$E$2:$E$1387) -> 0.54978355 | C7: =MEDIAN('Analysis Data'!$E$2:$E$1387) -> 1 | D7: =_xlfn.STDEV.S('Analysis Data'!$E$2:$E$1387) -> 0.497695 | E7: =MIN('Analysis Data'!$E$2:$E$1387) -> 0 | F7: =MAX('Analysis Data'!$E$2:$E$1387) -> 1 | G7: =COUNT('Analysis Data'!$E$2:$E$1387) -> 1386
A8: Endcap | B8: =AVERAGE('Analysis Data'!$F$2:$F$1387) -> 0.038239538 | C8: =MEDIAN('Analysis Data'!$F$2:$F$1387) -> 0 | D8: =_xlfn.STDEV.S('Analysis Data'!$F$2:$F$1387) -> 0.19184324 | E8: =MIN('Analysis Data'!$F$2:$F$1387) -> 0 | F8: =MAX('Analysis Data'!$F$2:$F$1387) -> 1 | G8: =COUNT('Analysis Data'!$F$2:$F$1387) -> 1386
A9: Demo | B9: =AVERAGE('Analysis Data'!$G$2:$G$1387) -> 0.058441558 | C9: =MEDIAN('Analysis Data'!$G$2:$G$1387) -> 0 | D9: =_xlfn.STDEV.S('Analysis Data'!$G$2:$G$1387) -> 0.23466119 | E9: =MIN('Analysis Data'!$G$2:$G$1387) -> 0 | F9: =MAX('Analysis Data'!$G$2:$G$1387) -> 1 | G9: =COUNT('Analysis Data'!$G$2:$G$1387) -> 1386
A10: D13 (Demo1-3) | B10: =AVERAGE('Analysis Data'!$H$2:$H$1387) -> 0.15656566 | C10: =MEDIAN('Analysis Data'!$H$2:$H$1387) -> 0 | D10: =_xlfn.STDEV.S('Analysis Data'!$H$2:$H$1387) -> 0.36352193 | E10: =MIN('Analysis Data'!$H$2:$H$1387) -> 0 | F10: =MAX('Analysis Data'!$H$2:$H$1387) -> 1 | G10: =COUNT('Analysis Data'!$H$2:$H$1387) -> 1386
A11: D45 (Demo4-5) | B11: =AVERAGE('Analysis Data'!$I$2:$I$1387) -> 0.075757576 | C11: =MEDIAN('Analysis Data'!$I$2:$I$1387) -> 0 | D11: =_xlfn.STDEV.S('Analysis Data'!$I$2:$I$1387) -> 0.26470535 | E11: =MIN('Analysis Data'!$I$2:$I$1387) -> 0 | F11: =MAX('Analysis Data'!$I$2:$I$1387) -> 1 | G11: =COUNT('Analysis Data'!$I$2:$I$1387) -> 1386
A12: Natural | B12: =AVERAGE('Analysis Data'!$J$2:$J$1387) -> 1.4487734 | C12: =MEDIAN('Analysis Data'!$J$2:$J$1387) -> 1 | D12: =_xlfn.STDEV.S('Analysis Data'!$J$2:$J$1387) -> 0.97509156 | E12: =MIN('Analysis Data'!$J$2:$J$1387) -> 0 | F12: =MAX('Analysis Data'!$J$2:$J$1387) -> 4 | G12: =COUNT('Analysis Data'!$J$2:$J$1387) -> 1386
A13: Fitness | B13: =AVERAGE('Analysis Data'!$K$2:$K$1387) -> 2.4761905 | C13: =MEDIAN('Analysis Data'!$K$2:$K$1387) -> 2 | D13: =_xlfn.STDEV.S('Analysis Data'!$K$2:$K$1387) -> 1.5927893 | E13: =MIN('Analysis Data'!$K$2:$K$1387) -> 0 | F13: =MAX('Analysis Data'!$K$2:$K$1387) -> 5 | G13: =COUNT('Analysis Data'!$K$2:$K$1387) -> 1386
A15: Unadjusted mean Sales: promotion = 1 vs 0 (Welch two-sample t-test)
A16: Promotion | B16: Mean (=1) | C16: Mean (=0) | D16: Difference | E16: N (=1) | F16: N (=0) | G16: SD (=1) | H16: SD (=0) | I16: Welch t | J16: Welch df | K16: p-value
A17: Demo (current week) | B17: =AVERAGEIF('Analysis Data'!$G$2:$G$1387,1,'Analysis Data'!$C$2:$C$1387) -> 400.50795 | C17: =AVERAGEIF('Analysis Data'!$G$2:$G$1387,0,'Analysis Data'!$C$2:$C$1387) -> 244.71599 | D17: =B17-C17 -> 155.79196 | E17: =COUNTIF('Analysis Data'!$G$2:$G$1387,1) -> 81 | F17: =COUNTIF('Analysis Data'!$G$2:$G$1387,0) -> 1305 | G17: {=_xlfn.STDEV.S(IF('Analysis Data'!$G$2:$G$1387=1,'Analysis Data'!$C$2:$C$1387))} -> 162.70749 | H17: {=_xlfn.STDEV.S(IF('Analysis Data'!$G$2:$G$1387=0,'Analysis Data'!$C$2:$C$1387))} -> 100.21154 | I17: =D17/SQRT(G17^2/E17+H17^2/F17) -> 8.5177829 | J17: =(G17^2/E17+H17^2/F17)^2/((G17^2/E17)^2/(E17-1)+(H17^2/F17)^2/(F17-1)) -> 83.808665 | K17: =_xlfn.T.DIST.2T(ABS(I17),J17) -> 6.0238074e-13
A18: Demo1-3 | B18: =AVERAGEIF('Analysis Data'!$H$2:$H$1387,1,'Analysis Data'!$C$2:$C$1387) -> 352.86975 | C18: =AVERAGEIF('Analysis Data'!$H$2:$H$1387,0,'Analysis Data'!$C$2:$C$1387) -> 235.43437 | D18: =B18-C18 -> 117.43539 | E18: =COUNTIF('Analysis Data'!$H$2:$H$1387,1) -> 217 | F18: =COUNTIF('Analysis Data'!$H$2:$H$1387,0) -> 1169 | G18: {=_xlfn.STDEV.S(IF('Analysis Data'!$H$2:$H$1387=1,'Analysis Data'!$C$2:$C$1387))} -> 136.94347 | H18: {=_xlfn.STDEV.S(IF('Analysis Data'!$H$2:$H$1387=0,'Analysis Data'!$C$2:$C$1387))} -> 94.765942 | I18: =D18/SQRT(G18^2/E18+H18^2/F18) -> 12.10584 | J18: =(G18^2/E18+H18^2/F18)^2/((G18^2/E18)^2/(E18-1)+(H18^2/F18)^2/(F18-1)) -> 255.73485 | K18: =_xlfn.T.DIST.2T(ABS(I18),J18) -> 5.9034953e-27
A19: Demo4-5 | B19: =AVERAGEIF('Analysis Data'!$I$2:$I$1387,1,'Analysis Data'!$C$2:$C$1387) -> 330.68614 | C19: =AVERAGEIF('Analysis Data'!$I$2:$I$1387,0,'Analysis Data'!$C$2:$C$1387) -> 247.52027 | D19: =B19-C19 -> 83.165864 | E19: =COUNTIF('Analysis Data'!$I$2:$I$1387,1) -> 105 | F19: =COUNTIF('Analysis Data'!$I$2:$I$1387,0) -> 1281 | G19: {=_xlfn.STDEV.S(IF('Analysis Data'!$I$2:$I$1387=1,'Analysis Data'!$C$2:$C$1387))} -> 106.11667 | H19: {=_xlfn.STDEV.S(IF('Analysis Data'!$I$2:$I$1387=0,'Analysis Data'!$C$2:$C$1387))} -> 109.05079 | I19: =D19/SQRT(G19^2/E19+H19^2/F19) -> 7.7042215 | J19: =(G19^2/E19+H19^2/F19)^2/((G19^2/E19)^2/(E19-1)+(H19^2/F19)^2/(F19-1)) -> 122.70961 | K19: =_xlfn.T.DIST.2T(ABS(I19),J19) -> 3.9005256e-12
A20: Endcap | B20: =AVERAGEIF('Analysis Data'!$F$2:$F$1387,1,'Analysis Data'!$C$2:$C$1387) -> 583.92496 | C20: =AVERAGEIF('Analysis Data'!$F$2:$F$1387,0,'Analysis Data'!$C$2:$C$1387) -> 240.69579 | D20: =B20-C20 -> 343.22917 | E20: =COUNTIF('Analysis Data'!$F$2:$F$1387,1) -> 53 | F20: =COUNTIF('Analysis Data'!$F$2:$F$1387,0) -> 1333 | G20: {=_xlfn.STDEV.S(IF('Analysis Data'!$F$2:$F$1387=1,'Analysis Data'!$C$2:$C$1387))} -> 265.9761 | H20: {=_xlfn.STDEV.S(IF('Analysis Data'!$F$2:$F$1387=0,'Analysis Data'!$C$2:$C$1387))} -> 74.43768 | I20: =D20/SQRT(G20^2/E20+H20^2/F20) -> 9.3800321 | J20: =(G20^2/E20+H20^2/F20)^2/((G20^2/E20)^2/(E20-1)+(H20^2/F20)^2/(F20-1)) -> 52.324361 | K20: =_xlfn.T.DIST.2T(ABS(I20),J20) -> 9.0369156e-13
A21: Sales Rep | B21: =AVERAGEIF('Analysis Data'!$E$2:$E$1387,1,'Analysis Data'!$C$2:$C$1387) -> 298.94889 | C21: =AVERAGEIF('Analysis Data'!$E$2:$E$1387,0,'Analysis Data'!$C$2:$C$1387) -> 198.71227 | D21: =B21-C21 -> 100.23662 | E21: =COUNTIF('Analysis Data'!$E$2:$E$1387,1) -> 762 | F21: =COUNTIF('Analysis Data'!$E$2:$E$1387,0) -> 624 | G21: {=_xlfn.STDEV.S(IF('Analysis Data'!$E$2:$E$1387=1,'Analysis Data'!$C$2:$C$1387))} -> 123.03375 | H21: {=_xlfn.STDEV.S(IF('Analysis Data'!$E$2:$E$1387=0,'Analysis Data'!$C$2:$C$1387))} -> 58.028094 | I21: =D21/SQRT(G21^2/E21+H21^2/F21) -> 19.9433 | J21: =(G21^2/E21+H21^2/F21)^2/((G21^2/E21)^2/(E21-1)+(H21^2/F21)^2/(F21-1)) -> 1128.8461 | K21: =_xlfn.T.DIST.2T(ABS(I21),J21) -> 4.8599039e-76
A23: Mean Sales by Sales Rep x Endcap cell
A24: Cell | B24: Mean Sales | C24: N
A25: No rep, no endcap | B25: =AVERAGEIFS('Analysis Data'!$C$2:$C$1387,'Analysis Data'!$E$2:$E$1387,0,'Analysis Data'!$F$2:$F$1387,0) -> 198.18336 | C25: =COUNTIFS('Analysis Data'!$E$2:$E$1387,0,'Analysis Data'!$F$2:$F$1387,0) -> 607
A26: No rep, endcap | B26: =AVERAGEIFS('Analysis Data'!$C$2:$C$1387,'Analysis Data'!$E$2:$E$1387,0,'Analysis Data'!$F$2:$F$1387,1) -> 217.59744 | C26: =COUNTIFS('Analysis Data'!$E$2:$E$1387,0,'Analysis Data'!$F$2:$F$1387,1) -> 17
A27: Rep, no endcap | B27: =AVERAGEIFS('Analysis Data'!$C$2:$C$1387,'Analysis Data'!$E$2:$E$1387,1,'Analysis Data'!$F$2:$F$1387,0) -> 276.23993 | C27: =COUNTIFS('Analysis Data'!$E$2:$E$1387,1,'Analysis Data'!$F$2:$F$1387,0) -> 726
A28: Rep, endcap | B28: =AVERAGEIFS('Analysis Data'!$C$2:$C$1387,'Analysis Data'!$E$2:$E$1387,1,'Analysis Data'!$F$2:$F$1387,1) -> 756.91295 | C28: =COUNTIFS('Analysis Data'!$E$2:$E$1387,1,'Analysis Data'!$F$2:$F$1387,1) -> 36

Sheet Correlations
A1: PAIRWISE CORRELATION MATRIX (Pearson, CORREL formulas)
B3: Sales | C3: Price | D3: Rep | E3: Endcap | F3: Demo | G3: Demo1-3 | H3: Demo4-5 | I3: Natural | J3: Fitness | K3: Endcap x Rep
A4: Sales | B4: =CORREL('Analysis Data'!$C$2:$C$1387,'Analysis Data'!$C$2:$C$1387) -> 1 | C4: =CORREL('Analysis Data'!$C$2:$C$1387,'Analysis Data'!$D$2:$D$1387) -> -0.018828588 | D4: =CORREL('Analysis Data'!$C$2:$C$1387,'Analysis Data'!$E$2:$E$1387) -> 0.44943995 | E4: =CORREL('Analysis Data'!$C$2:$C$1387,'Analysis Data'!$F$2:$F$1387) -> 0.59321576 | F4: =CORREL('Analysis Data'!$C$2:$C$1387,'Analysis Data'!$G$2:$G$1387) -> 0.32935805 | G4: =CORREL('Analysis Data'!$C$2:$C$1387,'Analysis Data'!$H$2:$H$1387) -> 0.38460204 | H4: =CORREL('Analysis Data'!$C$2:$C$1387,'Analysis Data'!$I$2:$I$1387) -> 0.19833063 | I4: =CORREL('Analysis Data'!$C$2:$C$1387,'Analysis Data'!$J$2:$J$1387) -> 0.062784251 | J4: =CORREL('Analysis Data'!$C$2:$C$1387,'Analysis Data'!$K$2:$K$1387) -> -0.031771848 | K4: =CORREL('Analysis Data'!$C$2:$C$1387,'Analysis Data'!$L$2:$L$1387) -> 0.74040731
A5: Price | B5: =CORREL('Analysis Data'!$D$2:$D$1387,'Analysis Data'!$C$2:$C$1387) -> -0.018828588 | C5: =CORREL('Analysis Data'!$D$2:$D$1387,'Analysis Data'!$D$2:$D$1387) -> 1 | D5: =CORREL('Analysis Data'!$D$2:$D$1387,'Analysis Data'!$E$2:$E$1387) -> 0.32890041 | E5: =CORREL('Analysis Data'!$D$2:$D$1387,'Analysis Data'!$F$2:$F$1387) -> -0.067293565 | F5: =CORREL('Analysis Data'!$D$2:$D$1387,'Analysis Data'!$G$2:$G$1387) -> 0.051664462 | G5: =CORREL('Analysis Data'!$D$2:$D$1387,'Analysis Data'!$H$2:$H$1387) -> -0.01509762 | H5: =CORREL('Analysis Data'!$D$2:$D$1387,'Analysis Data'!$I$2:$I$1387) -> 0.087935982 | I5: =CORREL('Analysis Data'!$D$2:$D$1387,'Analysis Data'!$J$2:$J$1387) -> -0.0048123855 | J5: =CORREL('Analysis Data'!$D$2:$D$1387,'Analysis Data'!$K$2:$K$1387) -> 0.071174912 | K5: =CORREL('Analysis Data'!$D$2:$D$1387,'Analysis Data'!$L$2:$L$1387) -> -0.058266802
A6: Rep | B6: =CORREL('Analysis Data'!$E$2:$E$1387,'Analysis Data'!$C$2:$C$1387) -> 0.44943995 | C6: =CORREL('Analysis Data'!$E$2:$E$1387,'Analysis Data'!$D$2:$D$1387) -> 0.32890041 | D6: =CORREL('Analysis Data'!$E$2:$E$1387,'Analysis Data'!$E$2:$E$1387) -> 1 | E6: =CORREL('Analysis Data'!$E$2:$E$1387,'Analysis Data'!$F$2:$F$1387) -> 0.0518869 | F6: =CORREL('Analysis Data'!$E$2:$E$1387,'Analysis Data'!$G$2:$G$1387) -> 0.1512641 | G6: =CORREL('Analysis Data'!$E$2:$E$1387,'Analysis Data'!$H$2:$H$1387) -> 0.24222744 | H6: =CORREL('Analysis Data'!$E$2:$E$1387,'Analysis Data'!$I$2:$I$1387) -> 0.13850847 | I6: =CORREL('Analysis Data'!$E$2:$E$1387,'Analysis Data'!$J$2:$J$1387) -> 0.089318908 | J6: =CORREL('Analysis Data'!$E$2:$E$1387,'Analysis Data'!$K$2:$K$1387) -> 0.057511255 | K6: =CORREL('Analysis Data'!$E$2:$E$1387,'Analysis Data'!$L$2:$L$1387) -> 0.14777439
A7: Endcap | B7: =CORREL('Analysis Data'!$F$2:$F$1387,'Analysis Data'!$C$2:$C$1387) -> 0.59321576 | C7: =CORREL('Analysis Data'!$F$2:$F$1387,'Analysis Data'!$D$2:$D$1387) -> -0.067293565 | D7: =CORREL('Analysis Data'!$F$2:$F$1387,'Analysis Data'!$E$2:$E$1387) -> 0.0518869 | E7: =CORREL('Analysis Data'!$F$2:$F$1387,'Analysis Data'!$F$2:$F$1387) -> 1 | F7: =CORREL('Analysis Data'!$F$2:$F$1387,'Analysis Data'!$G$2:$G$1387) -> 0.078630074 | G7: =CORREL('Analysis Data'!$F$2:$F$1387,'Analysis Data'!$H$2:$H$1387) -> 0.090093443 | H7: =CORREL('Analysis Data'!$F$2:$F$1387,'Analysis Data'!$I$2:$I$1387) -> -0.00021542548 | I7: =CORREL('Analysis Data'!$F$2:$F$1387,'Analysis Data'!$J$2:$J$1387) -> 0.081884463 | J7: =CORREL('Analysis Data'!$F$2:$F$1387,'Analysis Data'!$K$2:$K$1387) -> -0.059635101 | K7: =CORREL('Analysis Data'!$F$2:$F$1387,'Analysis Data'!$L$2:$L$1387) -> 0.81895777
A8: Demo | B8: =CORREL('Analysis Data'!$G$2:$G$1387,'Analysis Data'!$C$2:$C$1387) -> 0.32935805 | C8: =CORREL('Analysis Data'!$G$2:$G$1387,'Analysis Data'!$D$2:$D$1387) -> 0.051664462 | D8: =CORREL('Analysis Data'!$G$2:$G$1387,'Analysis Data'!$E$2:$E$1387) -> 0.1512641 | E8: =CORREL('Analysis Data'!$G$2:$G$1387,'Analysis Data'!$F$2:$F$1387) -> 0.078630074 | F8: =CORREL('Analysis Data'!$G$2:$G$1387,'Analysis Data'!$G$2:$G$1387) -> 1 | G8: =CORREL('Analysis Data'!$G$2:$G$1387,'Analysis Data'!$H$2:$H$1387) -> 0.036549317 | H8: =CORREL('Analysis Data'!$G$2:$G$1387,'Analysis Data'!$I$2:$I$1387) -> -0.013208807 | I8: =CORREL('Analysis Data'!$G$2:$G$1387,'Analysis Data'!$J$2:$J$1387) -> -0.0011064623 | J8: =CORREL('Analysis Data'!$G$2:$G$1387,'Analysis Data'!$K$2:$K$1387) -> 0.0066231384 | K8: =CORREL('Analysis Data'!$G$2:$G$1387,'Analysis Data'!$L$2:$L$1387) -> 0.094677756
A9: Demo1-3 | B9: =CORREL('Analysis Data'!$H$2:$H$1387,'Analysis Data'!$C$2:$C$1387) -> 0.38460204 | C9: =CORREL('Analysis Data'!$H$2:$H$1387,'Analysis Data'!$D$2:$D$1387) -> -0.01509762 | D9: =CORREL('Analysis Data'!$H$2:$H$1387,'Analysis Data'!$E$2:$E$1387) -> 0.24222744 | E9: =CORREL('Analysis Data'!$H$2:$H$1387,'Analysis Data'!$F$2:$F$1387) -> 0.090093443 | F9: =CORREL('Analysis Data'!$H$2:$H$1387,'Analysis Data'!$G$2:$G$1387) -> 0.036549317 | G9: =CORREL('Analysis Data'!$H$2:$H$1387,'Analysis Data'!$H$2:$H$1387) -> 1 | H9: =CORREL('Analysis Data'!$H$2:$H$1387,'Analysis Data'!$I$2:$I$1387) -> 0.011709819 | I9: =CORREL('Analysis Data'!$H$2:$H$1387,'Analysis Data'!$J$2:$J$1387) -> -0.0048556907 | J9: =CORREL('Analysis Data'!$H$2:$H$1387,'Analysis Data'!$K$2:$K$1387) -> 0.0083132341 | K9: =CORREL('Analysis Data'!$H$2:$H$1387,'Analysis Data'!$L$2:$L$1387) -> 0.10440063
A10: Demo4-5 | B10: =CORREL('Analysis Data'!$I$2:$I$1387,'Analysis Data'!$C$2:$C$1387) -> 0.19833063 | C10: =CORREL('Analysis Data'!$I$2:$I$1387,'Analysis Data'!$D$2:$D$1387) -> 0.087935982 | D10: =CORREL('Analysis Data'!$I$2:$I$1387,'Analysis Data'!$E$2:$E$1387) -> 0.13850847 | E10: =CORREL('Analysis Data'!$I$2:$I$1387,'Analysis Data'!$F$2:$F$1387) -> -0.00021542548 | F10: =CORREL('Analysis Data'!$I$2:$I$1387,'Analysis Data'!$G$2:$G$1387) -> -0.013208807 | G10: =CORREL('Analysis Data'!$I$2:$I$1387,'Analysis Data'!$H$2:$H$1387) -> 0.011709819 | H10: =CORREL('Analysis Data'!$I$2:$I$1387,'Analysis Data'!$I$2:$I$1387) -> 1 | I10: =CORREL('Analysis Data'!$I$2:$I$1387,'Analysis Data'!$J$2:$J$1387) -> 0.01364753 | J10: =CORREL('Analysis Data'!$I$2:$I$1387,'Analysis Data'!$K$2:$K$1387) -> -0.011987461 | K10: =CORREL('Analysis Data'!$I$2:$I$1387,'Analysis Data'!$L$2:$L$1387) -> -0.012467322
A11: Natural | B11: =CORREL('Analysis Data'!$J$2:$J$1387,'Analysis Data'!$C$2:$C$1387) -> 0.062784251 | C11: =CORREL('Analysis Data'!$J$2:$J$1387,'Analysis Data'!$D$2:$D$1387) -> -0.0048123855 | D11: =CORREL('Analysis Data'!$J$2:$J$1387,'Analysis Data'!$E$2:$E$1387) -> 0.089318908 | E11: =CORREL('Analysis Data'!$J$2:$J$1387,'Analysis Data'!$F$2:$F$1387) -> 0.081884463 | F11: =CORREL('Analysis Data'!$J$2:$J$1387,'Analysis Data'!$G$2:$G$1387) -> -0.0011064623 | G11: =CORREL('Analysis Data'!$J$2:$J$1387,'Analysis Data'!$H$2:$H$1387) -> -0.0048556907 | H11: =CORREL('Analysis Data'!$J$2:$J$1387,'Analysis Data'!$I$2:$I$1387) -> 0.01364753 | I11: =CORREL('Analysis Data'!$J$2:$J$1387,'Analysis Data'!$J$2:$J$1387) -> 1 | J11: =CORREL('Analysis Data'!$J$2:$J$1387,'Analysis Data'!$K$2:$K$1387) -> -0.085627579 | K11: =CORREL('Analysis Data'!$J$2:$J$1387,'Analysis Data'!$L$2:$L$1387) -> 0.05511849
A12: Fitness | B12: =CORREL('Analysis Data'!$K$2:$K$1387,'Analysis Data'!$C$2:$C$1387) -> -0.031771848 | C12: =CORREL('Analysis Data'!$K$2:$K$1387,'Analysis Data'!$D$2:$D$1387) -> 0.071174912 | D12: =CORREL('Analysis Data'!$K$2:$K$1387,'Analysis Data'!$E$2:$E$1387) -> 0.057511255 | E12: =CORREL('Analysis Data'!$K$2:$K$1387,'Analysis Data'!$F$2:$F$1387) -> -0.059635101 | F12: =CORREL('Analysis Data'!$K$2:$K$1387,'Analysis Data'!$G$2:$G$1387) -> 0.0066231384 | G12: =CORREL('Analysis Data'!$K$2:$K$1387,'Analysis Data'!$H$2:$H$1387) -> 0.0083132341 | H12: =CORREL('Analysis Data'!$K$2:$K$1387,'Analysis Data'!$I$2:$I$1387) -> -0.011987461 | I12: =CORREL('Analysis Data'!$K$2:$K$1387,'Analysis Data'!$J$2:$J$1387) -> -0.085627579 | J12: =CORREL('Analysis Data'!$K$2:$K$1387,'Analysis Data'!$K$2:$K$1387) -> 1 | K12: =CORREL('Analysis Data'!$K$2:$K$1387,'Analysis Data'!$L$2:$L$1387) -> -0.068781069
A13: Endcap x Rep | B13: =CORREL('Analysis Data'!$L$2:$L$1387,'Analysis Data'!$C$2:$C$1387) -> 0.74040731 | C13: =CORREL('Analysis Data'!$L$2:$L$1387,'Analysis Data'!$D$2:$D$1387) -> -0.058266802 | D13: =CORREL('Analysis Data'!$L$2:$L$1387,'Analysis Data'!$E$2:$E$1387) -> 0.14777439 | E13: =CORREL('Analysis Data'!$L$2:$L$1387,'Analysis Data'!$F$2:$F$1387) -> 0.81895777 | F13: =CORREL('Analysis Data'!$L$2:$L$1387,'Analysis Data'!$G$2:$G$1387) -> 0.094677756 | G13: =CORREL('Analysis Data'!$L$2:$L$1387,'Analysis Data'!$H$2:$H$1387) -> 0.10440063 | H13: =CORREL('Analysis Data'!$L$2:$L$1387,'Analysis Data'!$I$2:$I$1387) -> -0.012467322 | I13: =CORREL('Analysis Data'!$L$2:$L$1387,'Analysis Data'!$J$2:$J$1387) -> 0.05511849 | J13: =CORREL('Analysis Data'!$L$2:$L$1387,'Analysis Data'!$K$2:$K$1387) -> -0.068781069 | K13: =CORREL('Analysis Data'!$L$2:$L$1387,'Analysis Data'!$L$2:$L$1387) -> 1
A16: Reading: Sales correlates most with Endcap x Rep (0.74) and Endcap (0.59); Price has ~0 pairwise correlation with Sales, but a strongly negative partial effect once Sales Rep (r=0.33 with Price) is controlled. Predictors are only weakly correlated with each other (see VIF sheet).

Sheet Baseline Models
A1: BASELINE MODELS (0A, 0B, 0C) - single-predictor OLS using LINEST
A2: Unadjusted single-variable relationships. Price alone explains ~0% of variation; Endcap alone ~35%; Demo alone ~11%.
A3: Model 0A: Sales ~ Price
A6: INPUTS
A7: Dependent (Y) range | B7: 'Analysis Data'!C2:C1387
A8: Predictor (X) range | B8: 'Analysis Data'!D2:D1387
A10: CALCULATION: LINEST(Y,X,TRUE,TRUE) raw array (coefficients appear in REVERSE variable order; last column = intercept)
B11: Price | C11: Intercept
A12: Coefficient | B12: {=IFERROR(LINEST('Analysis Data'!$C$2:$C$1387,'Analysis Data'!$D$2:$D$1387,TRUE(),TRUE()),"")} -> -4.5058679 | C12: 272.32674
A13: Std error | B13: 6.4315502 | C13: 26.582768
A14: R² | SE(y) | B14: 0.00035451571 | C14: 111.01914
A15: F | df | B15: 0.49082375 | C15: 1384
A16: SSreg | SSres | B16: 6049.5252 | C16: 17058145
A19: OUTPUT: Regression statistics
A20: Multiple R | B20: =SQRT(INDEX('Baseline Models'!$B$12:$C$16,3,1)) -> 0.018828588
A21: R² | B21: =INDEX('Baseline Models'!$B$12:$C$16,3,1) -> 0.00035451571
A22: Adjusted R² | B22: =1-(1-'Baseline Models'!$B$21)*('Baseline Models'!$B$24-1)/'Baseline Models'!$B$26 -> -0.00036777149
A23: Standard error | B23: =INDEX('Baseline Models'!$B$12:$C$16,3,2) -> 111.01914
A24: Observations | B24: =COUNT('Analysis Data'!$C$2:$C$1387) -> 1386
A25: k (predictors) | B25: =1 -> 1
A26: df residual | B26: =INDEX('Baseline Models'!$B$12:$C$16,4,2) -> 1384
A27: F-statistic | B27: =INDEX('Baseline Models'!$B$12:$C$16,4,1) -> 0.49082375
A28: Significance F (model p-value) | B28: =_xlfn.F.DIST.RT('Baseline Models'!$B$27,'Baseline Models'!$B$25,'Baseline Models'!$B$26) -> 0.48367784
A29: SS regression | B29: =INDEX('Baseline Models'!$B$12:$C$16,5,1) -> 6049.5252
A30: SS residual | B30: =INDEX('Baseline Models'!$B$12:$C$16,5,2) -> 17058145
A31: SS total | B31: ='Baseline Models'!$B$29+'Baseline Models'!$B$30 -> 17064195
A33: OUTPUT: Coefficient table (t = b/SE; p = two-tailed T.DIST.2T; 95% CI = b ± T.INV.2T(0.05,df)·SE)
A34: Variable | B34: Coefficient | C34: Std error | D34: t-stat | E34: p-value | F34: Lower 95% | G34: Upper 95%
A35: Intercept | B35: =INDEX('Baseline Models'!$B$12:$C$16,1,2) -> 272.32674 | C35: =INDEX('Baseline Models'!$B$12:$C$16,2,2) -> 26.582768 | D35: =B35/C35 -> 10.244484 | E35: =_xlfn.T.DIST.2T(ABS(D35),'Baseline Models'!$B$26) -> 8.6387707e-24 | F35: =B35-_xlfn.T.INV.2T(0.05,'Baseline Models'!$B$26)*C35 -> 220.17986 | G35: =B35+_xlfn.T.INV.2T(0.05,'Baseline Models'!$B$26)*C35 -> 324.47361
A36: Price | B36: =INDEX('Baseline Models'!$B$12:$C$16,1,1) -> -4.5058679 | C36: =INDEX('Baseline Models'!$B$12:$C$16,2,1) -> 6.4315502 | D36: =B36/C36 -> -0.70058815 | E36: =_xlfn.T.DIST.2T(ABS(D36),'Baseline Models'!$B$26) -> 0.48367784 | F36: =B36-_xlfn.T.INV.2T(0.05,'Baseline Models'!$B$26)*C36 -> -17.122508 | G36: =B36+_xlfn.T.INV.2T(0.05,'Baseline Models'!$B$26)*C36 -> 8.1107726
A40: Model 0B: Sales ~ Demo
A43: INPUTS
A44: Dependent (Y) range | B44: 'Analysis Data'!C2:C1387
A45: Predictor (X) range | B45: 'Analysis Data'!G2:G1387
A47: CALCULATION: LINEST(Y,X,TRUE,TRUE) raw array (coefficients appear in REVERSE variable order; last column = intercept)
B48: Demo | C48: Intercept
A49: Coefficient | B49: {=IFERROR(LINEST('Analysis Data'!$C$2:$C$1387,'Analysis Data'!$G$2:$G$1387,TRUE(),TRUE()),"")} -> 155.79196 | C49: 244.71599
A50: Std error | B50: 12.005356 | C50: 2.9022575
A51: R² | SE(y) | B51: 0.10847672 | C51: 104.84342
A52: F | df | B52: 168.39918 | C52: 1384
...

Sheet Full MLR
A1: Model 1: Full business-driven MLR (no interaction)
A2: Sales = b0 + b1 Price + b2 Rep + b3 Endcap + b4 Demo + b5 Demo1-3 + b6 Demo4-5 + b7 Natural + b8 Fitness
A4: INPUTS
A5: Dependent (Y) range | B5: 'Analysis Data'!C2:C1387
A6: Predictor (X) range | B6: 'Analysis Data'!D2:K1387
A8: CALCULATION: LINEST(Y,X,TRUE,TRUE) raw array (coefficients appear in REVERSE variable order; last column = intercept)
B9: Fitness | C9: Natural | D9: D45 | E9: D13 | F9: Demo | G9: Endcap | H9: Rep | I9: Price | J9: Intercept
A10: Coefficient | B10: {=IFERROR(LINEST('Analysis Data'!$C$2:$C$1387,'Analysis Data'!$D$2:$K$1387,TRUE(),TRUE()),"")} -> -1.0196712 | C10: -1.5941682 | D10: 67.569811 | E10: 73.517171 | F10: 111.13285 | G10: 305.10212 | H10: 77.436914 | I10: -28.535365 | J10: 298.48813
A11: Std error | B11: 1.0840229 | C11: 1.7764007 | D11: 6.5419732 | E11: 4.8953839 | F11: 7.4036983 | G11: 9.0557374 | H11: 3.8644528 | I11: 3.9521527 | J11: 16.183094
A12: R² | SE(y) | B12: 0.67263527 | C12: 63.693025
A13: F | df | B13: 353.66468 | C13: 1377
A14: SSreg | SSres | B14: 11477979 | C14: 5586215.6
A17: OUTPUT: Regression statistics
A18: Multiple R | B18: =SQRT(INDEX('Full MLR'!$B$10:$J$14,3,1)) -> 0.82014344
A19: R² | B19: =INDEX('Full MLR'!$B$10:$J$14,3,1) -> 0.67263527
A20: Adjusted R² | B20: =1-(1-'Full MLR'!$B$19)*('Full MLR'!$B$22-1)/'Full MLR'!$B$24 -> 0.67073336
A21: Standard error | B21: =INDEX('Full MLR'!$B$10:$J$14,3,2) -> 63.693025
A22: Observations | B22: =COUNT('Analysis Data'!$C$2:$C$1387) -> 1386
A23: k (predictors) | B23: =8 -> 8
A24: df residual | B24: =INDEX('Full MLR'!$B$10:$J$14,4,2) -> 1377
A25: F-statistic | B25: =INDEX('Full MLR'!$B$10:$J$14,4,1) -> 353.66468
A26: Significance F (model p-value) | B26: =_xlfn.F.DIST.RT('Full MLR'!$B$25,'Full MLR'!$B$23,'Full MLR'!$B$24) -> 0
A27: SS regression | B27: =INDEX('Full MLR'!$B$10:$J$14,5,1) -> 11477979
A28: SS residual | B28: =INDEX('Full MLR'!$B$10:$J$14,5,2) -> 5586215.6
A29: SS total | B29: ='Full MLR'!$B$27+'Full MLR'!$B$28 -> 17064195
A31: OUTPUT: Coefficient table (t = b/SE; p = two-tailed T.DIST.2T; 95% CI = b ± T.INV.2T(0.05,df)·SE)
A32: Variable | B32: Coefficient | C32: Std error | D32: t-stat | E32: p-value | F32: Lower 95% | G32: Upper 95%
A33: Intercept | B33: =INDEX('Full MLR'!$B$10:$J$14,1,9) -> 298.48813 | C33: =INDEX('Full MLR'!$B$10:$J$14,2,9) -> 16.183094 | D33: =B33/C33 -> 18.444442 | E33: =_xlfn.T.DIST.2T(ABS(D33),'Full MLR'!$B$24) -> 4.6234257e-68 | F33: =B33-_xlfn.T.INV.2T(0.05,'Full MLR'!$B$24)*C33 -> 266.74195 | G33: =B33+_xlfn.T.INV.2T(0.05,'Full MLR'!$B$24)*C33 -> 330.23432
A34: Price | B34: =INDEX('Full MLR'!$B$10:$J$14,1,8) -> -28.535365 | C34: =INDEX('Full MLR'!$B$10:$J$14,2,8) -> 3.9521527 | D34: =B34/C34 -> -7.2202082 | E34: =_xlfn.T.DIST.2T(ABS(D34),'Full MLR'!$B$24) -> 8.5557844e-13 | F34: =B34-_xlfn.T.INV.2T(0.05,'Full MLR'!$B$24)*C34 -> -36.288257 | G34: =B34+_xlfn.T.INV.2T(0.05,'Full MLR'!$B$24)*C34 -> -20.782474
A35: Rep | B35: =INDEX('Full MLR'!$B$10:$J$14,1,7) -> 77.436914 | C35: =INDEX('Full MLR'!$B$10:$J$14,2,7) -> 3.8644528 | D35: =B35/C35 -> 20.038261 | E35: =_xlfn.T.DIST.2T(ABS(D35),'Full MLR'!$B$24) -> 1.3901294e-78 | F35: =B35-_xlfn.T.INV.2T(0.05,'Full MLR'!$B$24)*C35 -> 69.856062 | G35: =B35+_xlfn.T.INV.2T(0.05,'Full MLR'!$B$24)*C35 -> 85.017765
A36: Endcap | B36: =INDEX('Full MLR'!$B$10:$J$14,1,6) -> 305.10212 | C36: =INDEX('Full MLR'!$B$10:$J$14,2,6) -> 9.0557374 | D36: =B36/C36 -> 33.691582 | E36: =_xlfn.T.DIST.2T(ABS(D36),'Full MLR'!$B$24) -> 5.4001244e-182 | F36: =B36-_xlfn.T.INV.2T(0.05,'Full MLR'!$B$24)*C36 -> 287.33759 | G36: =B36+_xlfn.T.INV.2T(0.05,'Full MLR'!$B$24)*C36 -> 322.86666
A37: Demo | B37: =INDEX('Full MLR'!$B$10:$J$14,1,5) -> 111.13285 | C37: =INDEX('Full MLR'!$B$10:$J$14,2,5) -> 7.4036983 | D37: =B37/C37 -> 15.010451 | E37: =_xlfn.T.DIST.2T(ABS(D37),'Full MLR'!$B$24) -> 2.7785284e-47 | F37: =B37-_xlfn.T.INV.2T(0.05,'Full MLR'!$B$24)*C37 -> 96.609101 | G37: =B37+_xlfn.T.INV.2T(0.05,'Full MLR'!$B$24)*C37 -> 125.6566
A38: D13 | B38: =INDEX('Full MLR'!$B$10:$J$14,1,4) -> 73.517171 | C38: =INDEX('Full MLR'!$B$10:$J$14,2,4) -> 4.8953839 | D38: =B38/C38 -> 15.017652 | E38: =_xlfn.T.DIST.2T(ABS(D38),'Full MLR'!$B$24) -> 2.5309771e-47 | F38: =B38-_xlfn.T.INV.2T(0.05,'Full MLR'!$B$24)*C38 -> 63.913954 | G38: =B38+_xlfn.T.INV.2T(0.05,'Full MLR'!$B$24)*C38 -> 83.120388
A39: D45 | B39: =INDEX('Full MLR'!$B$10:$J$14,1,3) -> 67.569811 | C39: =INDEX('Full MLR'!$B$10:$J$14,2,3) -> 6.5419732 | D39: =B39/C39 -> 10.328659 | E39: =_xlfn.T.DIST.2T(ABS(D39),'Full MLR'!$B$24) -> 3.873164e-24 | F39: =B39-_xlfn.T.INV.2T(0.05,'Full MLR'!$B$24)*C39 -> 54.736499 | G39: =B39+_xlfn.T.INV.2T(0.05,'Full MLR'!$B$24)*C39 -> 80.403123
A40: Natural | B40: =INDEX('Full MLR'!$B$10:$J$14,1,2) -> -1.5941682 | C40: =INDEX('Full MLR'!$B$10:$J$14,2,2) -> 1.7764007 | D40: =B40/C40 -> -0.89741477 | E40: =_xlfn.T.DIST.2T(ABS(D40),'Full MLR'!$B$24) -> 0.36965451 | F40: =B40-_xlfn.T.INV.2T(0.05,'Full MLR'!$B$24)*C40 -> -5.0789126 | G40: =B40+_xlfn.T.INV.2T(0.05,'Full MLR'!$B$24)*C40 -> 1.8905762
A41: Fitness | B41: =INDEX('Full MLR'!$B$10:$J$14,1,1) -> -1.0196712 | C41: =INDEX('Full MLR'!$B$10:$J$14,2,1) -> 1.0840229 | D41: =B41/C41 -> -0.94063617 | E41: =_xlfn.T.DIST.2T(ABS(D41),'Full MLR'!$B$24) -> 0.34705632 | F41: =B41-_xlfn.T.INV.2T(0.05,'Full MLR'!$B$24)*C41 -> -3.1461861 | G41: =B41+_xlfn.T.INV.2T(0.05,'Full MLR'!$B$24)*C41 -> 1.1068438

Sheet Variable Selection
A1: Model 2: after variable selection (Natural, Fitness removed), no interaction
A2: Predictors retained by forward stepwise (p-in 0.05 / p-out 0.10) and by backward elimination on the no-interaction pool.
A4: INPUTS
A5: Dependent (Y) range | B5: 'Analysis Data'!C2:C1387
A6: Predictor (X) range | B6: 'Analysis Data'!D2:I1387
A8: CALCULATION: LINEST(Y,X,TRUE,TRUE) raw array (coefficients appear in REVERSE variable order; last column = intercept)
B9: D45 | C9: D13 | D9: Demo | E9: Endcap | F9: Rep | G9: Price | H9: Intercept
A10: Coefficient | B10: {=IFERROR(LINEST('Analysis Data'!$C$2:$C$1387,'Analysis Data'!$D$2:$I$1387,TRUE(),TRUE()),"")} -> 67.700203 | C10: 73.663094 | D10: 111.26053 | E10: 304.95972 | F10: 76.951206 | G10: -28.609165 | H10: 294.18904
A11: Std error | B11: 6.5392132 | C11: 4.8912512 | D11: 7.4009667 | E11: 9.0142802 | F11: 3.8408042 | G11: 3.9447142 | H11: 15.787096
A12: R² | SE(y) | B12: 0.67226502 | C12: 63.682803
A13: F | df | B13: 471.44467 | C13: 1379
A14: SSreg | SSres | B14: 11471661 | C14: 5592533.6
A17: OUTPUT: Regression statistics
A18: Multiple R | B18: =SQRT(INDEX('Variable Selection'!$B$10:$H$14,3,1)) -> 0.81991769
A19: R² | B19: =INDEX('Variable Selection'!$B$10:$H$14,3,1) -> 0.67226502
A20: Adjusted R² | B20: =1-(1-'Variable Selection'!$B$19)*('Variable Selection'!$B$22-1)/'Variable Selection'!$B$24 -> 0.67083905
A21: Standard error | B21: =INDEX('Variable Selection'!$B$10:$H$14,3,2) -> 63.682803
A22: Observations | B22: =COUNT('Analysis Data'!$C$2:$C$1387) -> 1386
A23: k (predictors) | B23: =6 -> 6
A24: df residual | B24: =INDEX('Variable Selection'!$B$10:$H$14,4,2) -> 1379
A25: F-statistic | B25: =INDEX('Variable Selection'!$B$10:$H$14,4,1) -> 471.44467
A26: Significance F (model p-value) | B26: =_xlfn.F.DIST.RT('Variable Selection'!$B$25,'Variable Selection'!$B$23,'Variable Selection'!$B$24) -> 0
A27: SS regression | B27: =INDEX('Variable Selection'!$B$10:$H$14,5,1) -> 11471661
A28: SS residual | B28: =INDEX('Variable Selection'!$B$10:$H$14,5,2) -> 5592533.6
A29: SS total | B29: ='Variable Selection'!$B$27+'Variable Selection'!$B$28 -> 17064195
A31: OUTPUT: Coefficient table (t = b/SE; p = two-tailed T.DIST.2T; 95% CI = b ± T.INV.2T(0.05,df)·SE)
A32: Variable | B32: Coefficient | C32: Std error | D32: t-stat | E32: p-value | F32: Lower 95% | G32: Upper 95%
A33: Intercept | B33: =INDEX('Variable Selection'!$B$10:$H$14,1,7) -> 294.18904 | C33: =INDEX('Variable Selection'!$B$10:$H$14,2,7) -> 15.787096 | D33: =B33/C33 -> 18.634779 | E33: =_xlfn.T.DIST.2T(ABS(D33),'Variable Selection'!$B$24) -> 2.6593234e-69 | F33: =B33-_xlfn.T.INV.2T(0.05,'Variable Selection'!$B$24)*C33 -> 263.21971 | G33: =B33+_xlfn.T.INV.2T(0.05,'Variable Selection'!$B$24)*C33 -> 325.15836
A34: Price | B34: =INDEX('Variable Selection'!$B$10:$H$14,1,6) -> -28.609165 | C34: =INDEX('Variable Selection'!$B$10:$H$14,2,6) -> 3.9447142 | D34: =B34/C34 -> -7.2525317 | E34: =_xlfn.T.DIST.2T(ABS(D34),'Variable Selection'!$B$24) -> 6.7964865e-13 | F34: =B34-_xlfn.T.INV.2T(0.05,'Variable Selection'!$B$24)*C34 -> -36.347454 | G34: =B34+_xlfn.T.INV.2T(0.05,'Variable Selection'!$B$24)*C34 -> -20.870875
A35: Rep | B35: =INDEX('Variable Selection'!$B$10:$H$14,1,5) -> 76.951206 | C35: =INDEX('Variable Selection'!$B$10:$H$14,2,5) -> 3.8408042 | D35: =B35/C35 -> 20.035181 | E35: =_xlfn.T.DIST.2T(ABS(D35),'Variable Selection'!$B$24) -> 1.4149284e-78 | F35: =B35-_xlfn.T.INV.2T(0.05,'Variable Selection'!$B$24)*C35 -> 69.416755 | G35: =B35+_xlfn.T.INV.2T(0.05,'Variable Selection'!$B$24)*C35 -> 84.485657
A36: Endcap | B36: =INDEX('Variable Selection'!$B$10:$H$14,1,4) -> 304.95972 | C36: =INDEX('Variable Selection'!$B$10:$H$14,2,4) -> 9.0142802 | D36: =B36/C36 -> 33.830734 | E36: =_xlfn.T.DIST.2T(ABS(D36),'Variable Selection'!$B$24) -> 3.5438091e-183 | F36: =B36-_xlfn.T.INV.2T(0.05,'Variable Selection'!$B$24)*C36 -> 287.27653 | G36: =B36+_xlfn.T.INV.2T(0.05,'Variable Selection'!$B$24)*C36 -> 322.6429
A37: Demo | B37: =INDEX('Variable Selection'!$B$10:$H$14,1,3) -> 111.26053 | C37: =INDEX('Variable Selection'!$B$10:$H$14,2,3) -> 7.4009667 | D37: =B37/C37 -> 15.033243 | E37: =_xlfn.T.DIST.2T(ABS(D37),'Variable Selection'!$B$24) -> 2.0449656e-47 | F37: =B37-_xlfn.T.INV.2T(0.05,'Variable Selection'!$B$24)*C37 -> 96.742163 | G37: =B37+_xlfn.T.INV.2T(0.05,'Variable Selection'!$B$24)*C37 -> 125.7789
A38: D13 | B38: =INDEX('Variable Selection'!$B$10:$H$14,1,2) -> 73.663094 | C38: =INDEX('Variable Selection'!$B$10:$H$14,2,2) -> 4.8912512 | D38: =B38/C38 -> 15.060174 | E38: =_xlfn.T.DIST.2T(ABS(D38),'Variable Selection'!$B$24) -> 1.4416497e-47 | F38: =B38-_xlfn.T.INV.2T(0.05,'Variable Selection'!$B$24)*C38 -> 64.067996 | G38: =B38+_xlfn.T.INV.2T(0.05,'Variable Selection'!$B$24)*C38 -> 83.258192
A39: D45 | B39: =INDEX('Variable Selection'!$B$10:$H$14,1,1) -> 67.700203 | C39: =INDEX('Variable Selection'!$B$10:$H$14,2,1) -> 6.5392132 | D39: =B39/C39 -> 10.352959 | E39: =_xlfn.T.DIST.2T(ABS(D39),'Variable Selection'!$B$24) -> 3.0525429e-24 | F39: =B39-_xlfn.T.INV.2T(0.05,'Variable Selection'!$B$24)*C39 -> 54.872322 | G39: =B39+_xlfn.T.INV.2T(0.05,'Variable Selection'!$B$24)*C39 -> 80.528084
A43: PARTIAL F-TEST: are Natural Retailers and Fitness Centers jointly needed? (Model 1 vs Model 2)
A44: Partial F = [(R²full - R²reduced)/q] / [(1 - R²full)/df_full]
A45: q (variables dropped) | B45: 2
A46: Partial F | B46: =(('Full MLR'!$B$19-'Variable Selection'!$B$19)/B45)/((1-'Full MLR'!$B$19)/'Full MLR'!$B$24) -> 0.77869214
A47: p-value | B47: =_xlfn.F.DIST.RT(B46,B45,'Full MLR'!$B$24) -> 0.45920795
A48: Decision (p-out = 0.10) | B48: =IF(B47>0.1,"Remove both","Keep") -> Remove both
...

Sheet Interaction Analysis
A1: Model 3: Full MLR + Endcap x Sales Rep
A2: Interaction variable EndRep = Endcap x Sales Rep (Analysis Data column L).
A4: INPUTS
A5: Dependent (Y) range | B5: 'Analysis Data'!C2:C1387
A6: Predictor (X) range | B6: 'Analysis Data'!D2:L1387
A8: CALCULATION: LINEST(Y,X,TRUE,TRUE) raw array (coefficients appear in REVERSE variable order; last column = intercept)
B9: EndRep | C9: Fitness | D9: Natural | E9: D45 | F9: D13 | G9: Demo | H9: Endcap | I9: Rep | J9: Price | K9: Intercept
A10: Coefficient | B10: {=IFERROR(LINEST('Analysis Data'!$C$2:$C$1387,'Analysis Data'!$D$2:$L$1387,TRUE(),TRUE()),"")} -> 454.06397 | C10: 0.21625304 | D10: 0.2133152 | E10: 74.584401 | F10: 73.387812 | G10: 106.76653 | H10: 0.46542443 | I10: 59.375305 | J10: -22.087416 | K10: 275.85608
A11: Std error | B11: 14.77576 | C11: 0.8360485 | D11: 1.3697195 | E11: 5.0447972 | F11: 3.7711773 | G11: 5.7052327 | H11: 12.121809 | I11: 3.0344582 | J11: 3.0517754 | K11: 12.488434
A12: R² | SE(y) | B12: 0.8058684 | C12: 49.06613
A13: F | df | B13: 634.66392 | C13: 1376
A14: SSreg | SSres | B14: 13751495 | C14: 3312699.5
A17: OUTPUT: Regression statistics
A18: Multiple R | B18: =SQRT(INDEX('Interaction Analysis'!$B$10:$K$14,3,1)) -> 0.89770173
A19: R² | B19: =INDEX('Interaction Analysis'!$B$10:$K$14,3,1) -> 0.8058684
A20: Adjusted R² | B20: =1-(1-'Interaction Analysis'!$B$19)*('Interaction Analysis'!$B$22-1)/'Interaction Analysis'!$B$24 -> 0.80459864
A21: Standard error | B21: =INDEX('Interaction Analysis'!$B$10:$K$14,3,2) -> 49.06613
A22: Observations | B22: =COUNT('Analysis Data'!$C$2:$C$1387) -> 1386
A23: k (predictors) | B23: =9 -> 9
A24: df residual | B24: =INDEX('Interaction Analysis'!$B$10:$K$14,4,2) -> 1376
A25: F-statistic | B25: =INDEX('Interaction Analysis'!$B$10:$K$14,4,1) -> 634.66392
A26: Significance F (model p-value) | B26: =_xlfn.F.DIST.RT('Interaction Analysis'!$B$25,'Interaction Analysis'!$B$23,'Interaction Analysis'!$B$24) -> 0
A27: SS regression | B27: =INDEX('Interaction Analysis'!$B$10:$K$14,5,1) -> 13751495
A28: SS residual | B28: =INDEX('Interaction Analysis'!$B$10:$K$14,5,2) -> 3312699.5
A29: SS total | B29: ='Interaction Analysis'!$B$27+'Interaction Analysis'!$B$28 -> 17064195
A31: OUTPUT: Coefficient table (t = b/SE; p = two-tailed T.DIST.2T; 95% CI = b ± T.INV.2T(0.05,df)·SE)
A32: Variable | B32: Coefficient | C32: Std error | D32: t-stat | E32: p-value | F32: Lower 95% | G32: Upper 95%
A33: Intercept | B33: =INDEX('Interaction Analysis'!$B$10:$K$14,1,10) -> 275.85608 | C33: =INDEX('Interaction Analysis'!$B$10:$K$14,2,10) -> 12.488434 | D33: =B33/C33 -> 22.088925 | E33: =_xlfn.T.DIST.2T(ABS(D33),'Interaction Analysis'!$B$24) -> 8.6722552e-93 | F33: =B33-_xlfn.T.INV.2T(0.05,'Interaction Analysis'!$B$24)*C33 -> 251.35765 | G33: =B33+_xlfn.T.INV.2T(0.05,'Interaction Analysis'!$B$24)*C33 -> 300.35451
A34: Price | B34: =INDEX('Interaction Analysis'!$B$10:$K$14,1,9) -> -22.087416 | C34: =INDEX('Interaction Analysis'!$B$10:$K$14,2,9) -> 3.0517754 | D34: =B34/C34 -> -7.2375628 | E34: =_xlfn.T.DIST.2T(ABS(D34),'Interaction Analysis'!$B$24) -> 7.5675458e-13 | F34: =B34-_xlfn.T.INV.2T(0.05,'Interaction Analysis'!$B$24)*C34 -> -28.074052 | G34: =B34+_xlfn.T.INV.2T(0.05,'Interaction Analysis'!$B$24)*C34 -> -16.10078
